Workbook
Name _Hlk167378349: rekod!$H$297

Sheet rekod
A1: REKOD PENDAFTARAN PERMOHONAN JTPKSAS | M1: =M525 -> 16 | N1: =N525 -> 79 | O1: =O525 -> 1 | P1: =P525 -> 28 | Q1: =Q525 -> 31 | R1: =R525 -> 19 | S1: =S525 -> 4 | T1: =T525 -> 79 | ... AC1: =AC525 -> 144
A3: Bil | B3: Kes | D3: PBT | E3: Tahun | F3: Keputusan | G3: Tarikh Kelulusan | H3: Tajuk | M3: MBSJ | N3: MPAJ | O3: MPK | P3: MBPJ | Q3: MPHS | R3: MBSA | S3: MPKL | T3: MPKj | U3: MPS | V3: MPKS | W3: MPSpg | X3: MDSB | Y3: MBDK | Z3: =J12 -> 0 | AA3: =J13 -> 0 | AB3: =J14 -> 0 | AC3: =J15 -> 0 | AD3: XDE KEPUTUSAN
A4: 1 | B4: PPC Glomac Sdn. Bhd. | C4: =IF(B4="","","vs") -> vs | D4: MBSA | E4: 2010 | F4: BERSETUJU | H4: Permohonan Serahbalik Dan Berimilik Semula Di Bawah Seksyen 204D KTN, Di Atas Lot 243, 395 Dan 397 Mukim Sungai Buloh, Daerah Petaling, Seksyen U17, 40160 Shah Alam, Selangor Darul Ehsan. | M4: =IF(D4=$M$3,1,"") | N4: =IF(D4=$N$3,1,"") | O4: =IF(D4=$O$3,1,"") | P4: =IF(D4=$P$3,1,"") | Q4: =IF(D4=$Q$3,1,"") | R4: =IF(D4=$R$3,1,"") -> 1 | S4: =IF(D4=$S$3,1,"") | T4: =IF(D4=$T$3,1,"") | U4: =IF(D4=$U$3,1,"") | V4: =IF(D4=$V$3,1,"") | W4: =IF(D4=$W$3,1,"") | X4: =IF(D4=$X$3,1,"") | Y4: =IF(#REF!=$X$3,1,"") -> #REF! | Z4: =IF(F4=$Z$3,1,"") | AA4: =IF(F4=$AA$3,1,"") | AB4: =IF(F4=$AB$3,1,"") | AC4: =IF(F4=$AC$3,1,"") | AD4: =IF(F4=$AE$3,1,"")
A5: =IF(B5="","",A4+1) -> 2 | B5: Turf Tech Sdn. Bhd. | C5: =IF(B5="","","vs") -> vs | D5: MPS | E5: 2010 | F5: BERSETUJU | H5: Permohonan Kelulusan Secara Serentak Bagi Pelan Kebenaran Merancang, Pelan Kerja Tanah, Pelan Jalan Dan Perparitan, Pelan Landskap, Pelan Bangunan Perumahan Di Atas Lot 163, Bandar Selayang, Daerah Gombak, Selangor Darul Ehsan. | M5: =IF(D5=$M$3,1,"") | N5: =IF(D5=$N$3,1,"") | O5: =IF(D5=$O$3,1,"") | P5: =IF(D5=$P$3,1,"") | Q5: =IF(D5=$Q$3,1,"") | R5: =IF(D5=$R$3,1,"") | S5: =IF(D5=$S$3,1,"") | T5: =IF(D5=$T$3,1,"") | U5: =IF(D5=$U$3,1,"") -> 1 | V5: =IF(D5=$V$3,1,"") | W5: =IF(D5=$W$3,1,"") | X5: =IF(D5=$X$3,1,"") | Y5: =IF(#REF!=$X$3,1,"") -> #REF! | Z5: =IF(F5=$Z$3,1,"") | AA5: =IF(F5=$AA$3,1,"") | AB5: =IF(F5=$AB$3,1,"") | AC5: =IF(F5=$AC$3,1,"") | AD5: =IF(F5=$AE$3,1,"")
A6: =IF(B6="","",A5+1) -> 3 | B6: Sin Heap Lee Development Sdn. Bhd. | C6: =IF(B6="","","vs") -> vs | D6: MPKj | E6: 2010 | F6: BERSETUJU | G6: bil 6/2010 | H6: Permohonan Kebenaran Merancang Cadangan Serahbalik Dan Berimilikan Semula Tanah Di Bawah Seksyen 204A Kanun Tanah Negara (KTN) Bagi Pembangunan Perumahan, Di Atas Lot PT.1495/1, PT.1495/2, PT.1495/3 Dan PT1495/4, Mukim Cheras, Daerah Hulu Langat, Selangor Darul Ehsan. | M6: =IF(D6=$M$3,1,"") | N6: =IF(D6=$N$3,1,"") | O6: =IF(D6=$O$3,1,"") | P6: =IF(D6=$P$3,1,"") | Q6: =IF(D6=$Q$3,1,"") | R6: =IF(D6=$R$3,1,"") | S6: =IF(D6=$S$3,1,"") | T6: =IF(D6=$T$3,1,"") -> 1 | U6: =IF(D6=$U$3,1,"") | V6: =IF(D6=$V$3,1,"") | W6: =IF(D6=$W$3,1,"") | X6: =IF(D6=$X$3,1,"") | Y6: =IF(#REF!=$X$3,1,"") -> #REF! | Z6: =IF(F6=$Z$3,1,"") | AA6: =IF(F6=$AA$3,1,"") | AB6: =IF(F6=$AB$3,1,"") | AC6: =IF(F6=$AC$3,1,"") | AD6: =IF(F6=$AE$3,1,"")
A7: =IF(B7="","",A6+1) -> 4 | B7: Trans Loyal Development Sdn. Bhd. | C7: =IF(B7="","","vs") -> vs | D7: MPKj | E7: 2010 | F7: BERSETUJU | H7: Permohonan Pindaan Kebenaran Merancang Terhadap Sebahagian Pelan Susunatur Yang Telah Diluluskan (Bil. Surat : (12) Dlm. MPKJ PB/KM1/68-2002) Bagi Cadangan Pembangunan Perumahan Dan Perniagaan, Di Atas Pt 69787 (Sebahagian Lot Asal Lot 41146) Mukim Kajang, Daerah Hulu Langat, Selangor Darul Ehsan. | M7: =IF(D7=$M$3,1,"") | N7: =IF(D7=$N$3,1,"") | O7: =IF(D7=$O$3,1,"") | P7: =IF(D7=$P$3,1,"") | Q7: =IF(D7=$Q$3,1,"") | R7: =IF(D7=$R$3,1,"") | S7: =IF(D7=$S$3,1,"") | T7: =IF(D7=$T$3,1,"") -> 1 | U7: =IF(D7=$U$3,1,"") | V7: =IF(D7=$V$3,1,"") | W7: =IF(D7=$W$3,1,"") | X7: =IF(D7=$X$3,1,"") | Y7: =IF(#REF!=$X$3,1,"") -> #REF! | Z7: =IF(F7=$Z$3,1,"") | AA7: =IF(F7=$AA$3,1,"") | AB7: =IF(F7=$AB$3,1,"") | AC7: =IF(F7=$AC$3,1,"") | AD7: =IF(F7=$AE$3,1,"")
A8: =IF(B8="","",A7+1) -> 5 | B8: Sunway Termuning Sdn. Bhd. | C8: =IF(B8="","","vs") -> vs | D8: MPKj | E8: 2010 | F8: DITANGGUHKAN | H8: Permohonan Kebenaran Merancang Untuk Pelan Susunatur Di Atas Lot 1316, 1352, 1355, 1401-1406, 1408-1410, 1412-1413, 1683-1684 Dan Sebahagian Lot 46953 (Lot 1351), Mukim Cheras, Daerah Hulu Langat, Selangor Darul Ehsan. | M8: =IF(D8=$M$3,1,"") | N8: =IF(D8=$N$3,1,"") | O8: =IF(D8=$O$3,1,"") | P8: =IF(D8=$P$3,1,"") | Q8: =IF(D8=$Q$3,1,"") | R8: =IF(D8=$R$3,1,"") | S8: =IF(D8=$S$3,1,"") | T8: =IF(D8=$T$3,1,"") -> 1 | U8: =IF(D8=$U$3,1,"") | V8: =IF(D8=$V$3,1,"") | W8: =IF(D8=$W$3,1,"") | X8: =IF(D8=$X$3,1,"") | Y8: =IF(#REF!=$X$3,1,"") -> #REF! | Z8: =IF(F8=$Z$3,1,"") | AA8: =IF(F8=$AA$3,1,"") | AB8: =IF(F8=$AB$3,1,"") | AC8: =IF(F8=$AC$3,1,"") | AD8: =IF(F8=$AE$3,1,"")
A9: =IF(B9="","",A8+1) -> 6 | B9: Prisma Cabaran Sdn. Bhd. | C9: =IF(B9="","","vs") -> vs | D9: MPSpg | E9: 2010 | F9: BERSETUJU | G9: bil 1/2011 | H9: Permohonan Kebenaran Merancang Bagi Cadangan Serah Balik Dan Pemberimilikan Semula Tanah, Di Bawah Seksyen 204d, Kanun Tanah Negara, Untuk Pembangunan Sekolah Agama Kiblah, Di Atas Lot 30774 (No. Hakmilik Pn) 43378), Mukim Dengkil, Daerah Sepang, Selangor Darul Ehsan Untuk Tetuan Prisma Cabaran Sdn. Bhd. | M9: =IF(D9=$M$3,1,"") | N9: =IF(D9=$N$3,1,"") | O9: =IF(D9=$O$3,1,"") | P9: =IF(D9=$P$3,1,"") | Q9: =IF(D9=$Q$3,1,"") | R9: =IF(D9=$R$3,1,"") | S9: =IF(D9=$S$3,1,"") | T9: =IF(D9=$T$3,1,"") | U9: =IF(D9=$U$3,1,"") | V9: =IF(D9=$V$3,1,"") | W9: =IF(D9=$W$3,1,"") -> 1 | X9: =IF(D9=$X$3,1,"") | Y9: =IF(#REF!=$X$3,1,"") -> #REF! | Z9: =IF(F9=$Z$3,1,"") | AA9: =IF(F9=$AA$3,1,"") | AB9: =IF(F9=$AB$3,1,"") | AC9: =IF(F9=$AC$3,1,"") | AD9: =IF(F9=$AE$3,1,"")
A10: =IF(B10="","",A9+1) -> 7 | B10: PKNS dan Spanland Sdn. Bhd. | C10: =IF(B10="","","vs") -> vs | D10: MPS | E10: 2010 | F10: BERSETUJU | H10: Permohonan Kebenaran Merancang Bagi Pindaan Pelan Susunatur (Bil. : PKNS/SPANLAND(PR)/G/0411PL1-A) bertarikh 31hb. Januari 2008) di atas lot PT 24263 HS(D) 49212 Lot PT 27264 HS (D) 49213, Lot PT 27265 HS(D) 52089 Dan Tanah Kerajaan Milik PKNS, Mukim Rawang, Daerah Gombak, Selangor | M10: =IF(D10=$M$3,1,"") | N10: =IF(D10=$N$3,1,"") | O10: =IF(D10=$O$3,1,"") | P10: =IF(D10=$P$3,1,"") | Q10: =IF(D10=$Q$3,1,"") | R10: =IF(D10=$R$3,1,"") | S10: =IF(D10=$S$3,1,"") | T10: =IF(D10=$T$3,1,"") | U10: =IF(D10=$U$3,1,"") -> 1 | V10: =IF(D10=$V$3,1,"") | W10: =IF(D10=$W$3,1,"") | X10: =IF(D10=$X$3,1,"") | Y10: =IF(#REF!=$X$3,1,"") -> #REF! | Z10: =IF(F10=$Z$3,1,"") | AA10: =IF(F10=$AA$3,1,"") | AB10: =IF(F10=$AB$3,1,"") | AC10: =IF(F10=$AC$3,1,"") | AD10: =IF(F10=$AE$3,1,"")
A11: =IF(B11="","",A10+1) -> 8 | B11: Dacing Kota Sdn. Bhd. | C11: =IF(B11="","","vs") -> vs | D11: MBSA | E11: 2010 | F11: BERSETUJU | G11: 41145 | H11: Permohonan Kebenaran Merancang Pelan Susunatur Bagi Pembangunan Perumahan Di Atas Tanah Seluas 16.80 Ekar, Mukim Bukit Raja, Daerah Petaling, Seksyen U10, Shah Alam | M11: =IF(D11=$M$3,1,"") | N11: =IF(D11=$N$3,1,"") | O11: =IF(D11=$O$3,1,"") | P11: =IF(D11=$P$3,1,"") | Q11: =IF(D11=$Q$3,1,"") | R11: =IF(D11=$R$3,1,"") -> 1 | S11: =IF(D11=$S$3,1,"") | T11: =IF(D11=$T$3,1,"") | U11: =IF(D11=$U$3,1,"") | V11: =IF(D11=$V$3,1,"") | W11: =IF(D11=$W$3,1,"") | X11: =IF(D11=$X$3,1,"") | Y11: =IF(#REF!=$X$3,1,"") -> #REF! | Z11: =IF(F11=$Z$3,1,"") | AA11: =IF(F11=$AA$3,1,"") | AB11: =IF(F11=$AB$3,1,"") | AC11: =IF(F11=$AC$3,1,"") | AD11: =IF(F11=$AE$3,1,"")
A12: =IF(B12="","",A11+1) -> 9 | B12: Kenangan Motivasi Sdn. Bhd. | C12: =IF(B12="","","vs") -> vs | D12: MBSA | E12: 2010 | F12: BERSETUJU | G12: bil 5/2010 7/9/2010 | H12: Permohonan Kebenaran Merancang Pelan Susunatur Bagi Pembangunan Perumahan Di Atas Lot Kompartment 32, Tanah Hutan Simpan Bukit Cherakah Seluas 100 Ekar, Mukim Bukit Raja, Daerah Petaling, Seksyen U10, Shah Alam Selangor | M12: =IF(D12=$M$3,1,"") | N12: =IF(D12=$N$3,1,"") | O12: =IF(D12=$O$3,1,"") | P12: =IF(D12=$P$3,1,"") | Q12: =IF(D12=$Q$3,1,"") | R12: =IF(D12=$R$3,1,"") -> 1 | S12: =IF(D12=$S$3,1,"") | T12: =IF(D12=$T$3,1,"") | U12: =IF(D12=$U$3,1,"") | V12: =IF(D12=$V$3,1,"") | W12: =IF(D12=$W$3,1,"") | X12: =IF(D12=$X$3,1,"") | Y12: =IF(#REF!=$X$3,1,"") -> #REF! | Z12: =IF(F12=$Z$3,1,"") | AA12: =IF(F12=$AA$3,1,"") | AB12: =IF(F12=$AB$3,1,"") | AC12: =IF(F12=$AC$3,1,"") | AD12: =IF(F12=$AE$3,1,"")
A13: =IF(B13="","",A12+1) -> 10 | B13: BASCO Sdn. Bhd. | C13: =IF(B13="","","vs") -> vs | D13: MBSA | E13: 2010 | F13: BERSETUJU | H13: Permohonan Kebenaran Merancang Pelan Susunatur Bagi Cadangan Pembangunan Perumahan Dan Perdagangan, Di Atas Tanah Pemberimilikan Seluas 200 Ekar, Seksyen U10, Shah Alam, Mukim Bukit Raja, Daerah Petaling, Selangor Darul Ehsan | M13: =IF(D13=$M$3,1,"") | N13: =IF(D13=$N$3,1,"") | O13: =IF(D13=$O$3,1,"") | P13: =IF(D13=$P$3,1,"") | Q13: =IF(D13=$Q$3,1,"") | R13: =IF(D13=$R$3,1,"") -> 1 | S13: =IF(D13=$S$3,1,"") | T13: =IF(D13=$T$3,1,"") | U13: =IF(D13=$U$3,1,"") | V13: =IF(D13=$V$3,1,"") | W13: =IF(D13=$W$3,1,"") | X13: =IF(D13=$X$3,1,"") | Y13: =IF(#REF!=$X$3,1,"") -> #REF! | Z13: =IF(F13=$Z$3,1,"") | AA13: =IF(F13=$AA$3,1,"") | AB13: =IF(F13=$AB$3,1,"") | AC13: =IF(F13=$AC$3,1,"") | AD13: =IF(F13=$AE$3,1,"")
A14: =IF(B14="","",A13+1) -> 11 | B14: TPPT Sdn. Bhd. | C14: =IF(B14="","","vs") -> vs | D14: MPS | E14: 2010 | F14: BERSETUJU | H14: Permohonan Kebenaran Merancang Bagi Cadangan Pelan Induk Di Bukit Serai, Mukim Rawang, Daerah Gombak, Selangor Darul Ehsan | M14: =IF(D14=$M$3,1,"") | N14: =IF(D14=$N$3,1,"") | O14: =IF(D14=$O$3,1,"") | P14: =IF(D14=$P$3,1,"") | Q14: =IF(D14=$Q$3,1,"") | R14: =IF(D14=$R$3,1,"") | S14: =IF(D14=$S$3,1,"") | T14: =IF(D14=$T$3,1,"") | U14: =IF(D14=$U$3,1,"") -> 1 | V14: =IF(D14=$V$3,1,"") | W14: =IF(D14=$W$3,1,"") | X14: =IF(D14=$X$3,1,"") | Y14: =IF(#REF!=$X$3,1,"") -> #REF! | Z14: =IF(F14=$Z$3,1,"") | AA14: =IF(F14=$AA$3,1,"") | AB14: =IF(F14=$AB$3,1,"") | AC14: =IF(F14=$AC$3,1,"") | AD14: =IF(F14=$AE$3,1,"")
A15: =IF(B15="","",A14+1) -> 12 | B15: Granstep Development Sdn. Bhd. | C15: =IF(B15="","","vs") -> vs | D15: MPAJ | E15: 2010 | F15: DITANGGUHKAN | H15: Permohonan Kebenaran Merancang Bagi Cadangan Pembangunan Perumahan Di Atas Lot 1287 (PT 30517, HS(D) 34803) Seluas 11.84 hektar (29.28 ekar), Bandar Ampang, Daerah Hulu Langat, Selangor Darul Ehsan Untuk Tetuan Granstep Development Sdn. Bhd. | M15: =IF(D15=$M$3,1,"") | N15: =IF(D15=$N$3,1,"") -> 1 | O15: =IF(D15=$O$3,1,"") | P15: =IF(D15=$P$3,1,"") | Q15: =IF(D15=$Q$3,1,"") | R15: =IF(D15=$R$3,1,"") | S15: =IF(D15=$S$3,1,"") | T15: =IF(D15=$T$3,1,"") | U15: =IF(D15=$U$3,1,"") | V15: =IF(D15=$V$3,1,"") | W15: =IF(D15=$W$3,1,"") | X15: =IF(D15=$X$3,1,"") | Y15: =IF(#REF!=$X$3,1,"") -> #REF! | Z15: =IF(F15=$Z$3,1,"") | AA15: =IF(F15=$AA$3,1,"") | AB15: =IF(F15=$AB$3,1,"") | AC15: =IF(F15=$AC$3,1,"") | AD15: =IF(F15=$AE$3,1,"")
A16: =IF(B16="","",A15+1) -> 13 | B16: Dijaya Property Sdn. Bhd. | C16: =IF(B16="","","vs") -> vs | D16: MPKj | E16: 2010 | F16: BERSETUJU | H16: Permohonan Pecah Sempadan Dan Tukar Syarat Tanah Secara Serentak Di Bawah Seksyen 124a Kanun Tanah Negara 1965 Dan Pembangunan 90 Unit Rumah Teres Strata Di Bawah Seksyen 6(1a) Akta 318 (Akta Hakmilik Strata 1985) Di Atas Lot 5717 Dan 1953, Mukim Kajang, Daerah Hulu Langat, Selangor Darul Ehsan. | M16: =IF(D16=$M$3,1,"") | N16: =IF(D16=$N$3,1,"") | O16: =IF(D16=$O$3,1,"") | P16: =IF(D16=$P$3,1,"") | Q16: =IF(D16=$Q$3,1,"") | R16: =IF(D16=$R$3,1,"") | S16: =IF(D16=$S$3,1,"") | T16: =IF(D16=$T$3,1,"") -> 1 | U16: =IF(D16=$U$3,1,"") | V16: =IF(D16=$V$3,1,"") | W16: =IF(D16=$W$3,1,"") | X16: =IF(D16=$X$3,1,"") | Y16: =IF(#REF!=$X$3,1,"") -> #REF! | Z16: =IF(F16=$Z$3,1,"") | AA16: =IF(F16=$AA$3,1,"") | AB16: =IF(F16=$AB$3,1,"") | AC16: =IF(F16=$AC$3,1,"") | AD16: =IF(F16=$AE$3,1,"")
A17: =IF(B17="","",A16+1) -> 14 | B17: Wangmatic Sdn. Bhd. | C17: =IF(B17="","","vs") -> vs | D17: MPKj | E17: 2010 | F17: BERSETUJU | H17: Permohonan Kebenaran Merancang Bagi Tujuan Tukar Syarat Daripada Tiada Kepada Bangunan Perumahan Di Bawah Seksyen 124a, Kanun Tanah Negara Di Atas Lot 2717, Mukim Kajang, Daerah Hulu Langat, Selangor Darul Ehsan | M17: =IF(D17=$M$3,1,"") | N17: =IF(D17=$N$3,1,"") | O17: =IF(D17=$O$3,1,"") | P17: =IF(D17=$P$3,1,"") | Q17: =IF(D17=$Q$3,1,"") | R17: =IF(D17=$R$3,1,"") | S17: =IF(D17=$S$3,1,"") | T17: =IF(D17=$T$3,1,"") -> 1 | U17: =IF(D17=$U$3,1,"") | V17: =IF(D17=$V$3,1,"") | W17: =IF(D17=$W$3,1,"") | X17: =IF(D17=$X$3,1,"") | Y17: =IF(#REF!=$X$3,1,"") -> #REF! | Z17: =IF(F17=$Z$3,1,"") | AA17: =IF(F17=$AA$3,1,"") | AB17: =IF(F17=$AB$3,1,"") | AC17: =IF(F17=$AC$3,1,"") | AD17: =IF(F17=$AE$3,1,"")
A18: =IF(B18="","",A17+1) -> 15 | B18: Prisma Cabaran Sdn. Bhd. | C18: =IF(B18="","","vs") -> vs | D18: MPSpg | E18: 2010 | F18: DITANGGUHKAN | H18: Permohonan Kebenaran Merancang Bagi Cadangan Serah Balik Dan Pemberimilikan Semula Tanah Di Bawah Seksyen 204d, Kanun Tanah Negara (Ktn) Untuk Pembangunan Sekolah Agama Kiblah Dan Mahad Tahfiz, Di Atas Lot 30774 No. Hakmilik Pn 49378 (Pt17124), Mukim Dengkil, Daerah Sepang, Selangor Darul Ehsan. | M18: =IF(D18=$M$3,1,"") | N18: =IF(D18=$N$3,1,"") | O18: =IF(D18=$O$3,1,"") | P18: =IF(D18=$P$3,1,"") | Q18: =IF(D18=$Q$3,1,"") | R18: =IF(D18=$R$3,1,"") | S18: =IF(D18=$S$3,1,"") | T18: =IF(D18=$T$3,1,"") | U18: =IF(D18=$U$3,1,"") | V18: =IF(D18=$V$3,1,"") | W18: =IF(D18=$W$3,1,"") -> 1 | X18: =IF(D18=$X$3,1,"") | Y18: =IF(#REF!=$X$3,1,"") -> #REF! | Z18: =IF(F18=$Z$3,1,"") | AA18: =IF(F18=$AA$3,1,"") | AB18: =IF(F18=$AB$3,1,"") | AC18: =IF(F18=$AC$3,1,"") | AD18: =IF(F18=$AE$3,1,"")
A19: =IF(B19="","",A18+1) -> 16 | B19: B.U. Developments Sdn. Bhd. | C19: =IF(B19="","","vs") -> vs | D19: MPAJ | E19: 2010 | F19: BERSETUJU | G19: bil 6/2010 | H19: Permohonan Kebenaran Merancang Bagi Cadangan Pembangunan Perniagaan yang Mengandungi Blok A, Blok B dan Blok C Serta meminda Syarat Nyata Tanah Daripada Bangunan Kediaman Kepada Perniagaan Secara Serentak Di Bawah Seksyen 124A Kanun Tanah Negara (KTN) Di Atas Lot 322 (GM53), Mukim Ulu Kelang, Daerah Gombak, Selangor Darul Ehsan. | M19: =IF(D19=$M$3,1,"") | N19: =IF(D19=$N$3,1,"") -> 1 | O19: =IF(D19=$O$3,1,"") | P19: =IF(D19=$P$3,1,"") | Q19: =IF(D19=$Q$3,1,"") | R19: =IF(D19=$R$3,1,"") | S19: =IF(D19=$S$3,1,"") | T19: =IF(D19=$T$3,1,"") | U19: =IF(D19=$U$3,1,"") | V19: =IF(D19=$V$3,1,"") | W19: =IF(D19=$W$3,1,"") | X19: =IF(D19=$X$3,1,"") | Y19: =IF(#REF!=$X$3,1,"") -> #REF! | Z19: =IF(F19=$Z$3,1,"") | AA19: =IF(F19=$AA$3,1,"") | AB19: =IF(F19=$AB$3,1,"") | AC19: =IF(F19=$AC$3,1,"") | AD19: =IF(F19=$AE$3,1,"")
A20: =IF(B20="","",A19+1) -> 17 | B20: Majlis Agama Islam Selangor (MAIS). | C20: =IF(B20="","","vs") -> vs | D20: MDHS | E20: 2010 | F20: BERSETUJU | H20: Permohonan Kebenaran Merancang Bagi Cadangan Pembangunan Pusat Latihan Saudara Baru ( Baitul Hikmah) Di Atas Sebahagian Hakmilik HSD 40183 PT 8789, Mukim Hulu Yam, Daerah Hulu Selangor, Selangor Darul Ehsan. | M20: =IF(D20=$M$3,1,"") | N20: =IF(D20=$N$3,1,"") | O20: =IF(D20=$O$3,1,"") | P20: =IF(D20=$P$3,1,"") | Q20: =IF(D20=$Q$3,1,"") | R20: =IF(D20=$R$3,1,"") | S20: =IF(D20=$S$3,1,"") | T20: =IF(D20=$T$3,1,"") | U20: =IF(D20=$U$3,1,"") | V20: =IF(D20=$V$3,1,"") | W20: =IF(D20=$W$3,1,"") | X20: =IF(D20=$X$3,1,"") | Y20: =IF(#REF!=$X$3,1,"") -> #REF! | Z20: =IF(F20=$Z$3,1,"") | AA20: =IF(F20=$AA$3,1,"") | AB20: =IF(F20=$AB$3,1,"") | AC20: =IF(F20=$AC$3,1,"") | AD20: =IF(F20=$AE$3,1,"")
A21: =IF(B21="","",A20+1) -> 18 | B21: Tanming Indah Sdn. Bhd. | C21: =IF(B21="","","vs") -> vs | D21: MPKj | E21: 2010 | F21: BERSETUJU | G21: bil 6/2010 | H21: Permohonan Kebenaran Merancang Bagi Pindaan Terhapadap Pelan Yang Telah Diluluskan (Pelan Bil.MPKj/PB/KM/113-2004) Di Atas Lot 12681, Mukim Kajang, Daerah Hulu Langat, Selangor Darul Ehsan. | M21: =IF(D21=$M$3,1,"") | N21: =IF(D21=$N$3,1,"") | O21: =IF(D21=$O$3,1,"") | P21: =IF(D21=$P$3,1,"") | Q21: =IF(D21=$Q$3,1,"") | R21: =IF(D21=$R$3,1,"") | S21: =IF(D21=$S$3,1,"") | T21: =IF(D21=$T$3,1,"") -> 1 | U21: =IF(D21=$U$3,1,"") | V21: =IF(D21=$V$3,1,"") | W21: =IF(D21=$W$3,1,"") | X21: =IF(D21=$X$3,1,"") | Y21: =IF(#REF!=$X$3,1,"") -> #REF! | Z21: =IF(F21=$Z$3,1,"") | AA21: =IF(F21=$AA$3,1,"") | AB21: =IF(F21=$AB$3,1,"") | AC21: =IF(F21=$AC$3,1,"") | AD21: =IF(F21=$AE$3,1,"")
A22: =IF(B22="","",A21+1) -> 19 | B22: SMS Development Sdn. Bhd. | C22: =IF(B22="","","vs") -> vs | D22: MPKj | E22: 2010 | F22: BERSETUJU | H22: Permohonan Kebenaran Merancang Bagi Cadangan Pelan Susunatur Industri Berkembar 56 Unit Di Atas Lot 19003 Sekxsyen 19, Bandar Rawang, Daerah Gombak, Selangor Darul Ehsan | M22: =IF(D22=$M$3,1,"") | N22: =IF(D22=$N$3,1,"") | O22: =IF(D22=$O$3,1,"") | P22: =IF(D22=$P$3,1,"") | Q22: =IF(D22=$Q$3,1,"") | R22: =IF(D22=$R$3,1,"") | S22: =IF(D22=$S$3,1,"") | T22: =IF(D22=$T$3,1,"") -> 1 | U22: =IF(D22=$U$3,1,"") | V22: =IF(D22=$V$3,1,"") | W22: =IF(D22=$W$3,1,"") | X22: =IF(D22=$X$3,1,"") | Y22: =IF(#REF!=$X$3,1,"") -> #REF! | Z22: =IF(F22=$Z$3,1,"") | AA22: =IF(F22=$AA$3,1,"") | AB22: =IF(F22=$AB$3,1,"") | AC22: =IF(F22=$AC$3,1,"") | AD22: =IF(F22=$AE$3,1,"")
B23: Tetuan Cheras Hong Soon Development Sdn. Bhd. | D23: MPKj | E23: 2010 | F23: BERSETUJU | M23: =IF(D23=$M$3,1,"") | N23: =IF(D23=$N$3,1,"") | O23: =IF(D23=$O$3,1,"") | P23: =IF(D23=$P$3,1,"") | Q23: =IF(D23=$Q$3,1,"") | R23: =IF(D23=$R$3,1,"") | S23: =IF(D23=$S$3,1,"") | T23: =IF(D23=$T$3,1,"") -> 1 | U23: =IF(D23=$U$3,1,"") | V23: =IF(D23=$V$3,1,"") | W23: =IF(D23=$W$3,1,"") | X23: =IF(D23=$X$3,1,"") | Y23: =IF(#REF!=$X$3,1,"") -> #REF! | AA23: =IF(F23=$AA$3,1,"") | AB23: =IF(F23=$AB$3,1,"") | AC23: =IF(F23=$AC$3,1,"") | AD23: =IF(F23=$AE$3,1,"")
A24: =IF(B24="","",A22+1) -> 20 | B24: Mammoth Empire Land Sdn. Bhd. | C24: =IF(B24="","","vs") -> vs | D24: MBPJ | E24: 2010 | F24: BERSETUJU | G24: bil 2/2011 | H24: Permohonan Kebenaran Merancang Bagi Cadangan Pecah Sempadan Mengikut Seksyen 135 (Kanun Tanah Negara 1965) Dan Pembangunan 795 Unit Rumah Teres 3 Tingkat Serta 1 Tingkat Tempat Letak kereta (Permilikan Berstrata Mengikut Seksyen 6, Akta Hakmilik Strata 1985) Di Atas Lot 44012 HSD 222396, Mukim Sungai Buloh, Daerah Petaling, Selangor Darul Ehsan. | M24: =IF(D24=$M$3,1,"") | N24: =IF(D24=$N$3,1,"") | O24: =IF(D24=$O$3,1,"") | P24: =IF(D24=$P$3,1,"") -> 1 | Q24: =IF(D24=$Q$3,1,"") | R24: =IF(D24=$R$3,1,"") | S24: =IF(D24=$S$3,1,"") | T24: =IF(D24=$T$3,1,"") | U24: =IF(D24=$U$3,1,"") | V24: =IF(D24=$V$3,1,"") | W24: =IF(D24=$W$3,1,"") | X24: =IF(D24=$X$3,1,"") | Y24: =IF(#REF!=$X$3,1,"") -> #REF! | Z24: =IF(F24=$Z$3,1,"") | AA24: =IF(F24=$AA$3,1,"") | AB24: =IF(F24=$AB$3,1,"") | AC24: =IF(F24=$AC$3,1,"") | AD24: =IF(F24=$AE$3,1,"")
A25: =IF(B25="","",A24+1) -> 21 | B25: Permodalan Negeri Selangor Berhad (PNSB) | C25: =IF(B25="","","vs") -> vs | D25: MBPJ | E25: 2010 | F25: BERSETUJU | G25: bil 1/2011 | H25: Cadangan Projek Perumahan Dimajukan Secara Usahasama Di Antara Setiausaha Kerajaan Negeri Selangor (Perbadanan) Dengan Syarikat Tetuan Agro Fresh (M) Sdn. Bhd. Pembangunan Perumahan Di Atas Lot 23739 (Dahulu Lot 1999), 23740 (Dahulu Lot 3505) Dan 23741 (Lot 3587) Mukim Sungai Buloh Daerah Petaling Selangor Darul Ehsan. | M25: =IF(D25=$M$3,1,"") | N25: =IF(D25=$N$3,1,"") | O25: =IF(D25=$O$3,1,"") | P25: =IF(D25=$P$3,1,"") -> 1 | Q25: =IF(D25=$Q$3,1,"") | R25: =IF(D25=$R$3,1,"") | S25: =IF(D25=$S$3,1,"") | T25: =IF(D25=$T$3,1,"") | U25: =IF(D25=$U$3,1,"") | V25: =IF(D25=$V$3,1,"") | W25: =IF(D25=$W$3,1,"") | X25: =IF(D25=$X$3,1,"") | Y25: =IF(#REF!=$X$3,1,"") -> #REF! | Z25: =IF(F25=$Z$3,1,"") | AA25: =IF(F25=$AA$3,1,"") | AB25: =IF(F25=$AB$3,1,"") | AC25: =IF(F25=$AC$3,1,"") | AD25: =IF(F25=$AE$3,1,"")
A26: =IF(B26="","",A25+1) -> 22 | B26: Restu Mantap Sdn. Bhd. | C26: =IF(#REF!="","","vs") -> #REF! | D26: MBSA | E26: 2010 | F26: BERSETUJU | H26: Permohonan Kebenaran Merancang Bagi Cadangan Pelan Susunatur Perumahan Di Atas Kompartmen 35, Hutan Simpan Bukit Cherakah, Mukim Bukit Raja, Daerah Petaling, Seksyen U10, Shah Alam, Selangor Darul Ehsan. | M26: =IF(D26=$M$3,1,"") | N26: =IF(D26=$N$3,1,"") | O26: =IF(D26=$O$3,1,"") | P26: =IF(D26=$P$3,1,"") | Q26: =IF(D26=$Q$3,1,"") | R26: =IF(D26=$R$3,1,"") -> 1 | S26: =IF(D26=$S$3,1,"") | T26: =IF(D26=$T$3,1,"") | U26: =IF(D26=$U$3,1,"") | V26: =IF(D26=$V$3,1,"") | W26: =IF(D26=$W$3,1,"") | X26: =IF(D26=$X$3,1,"") | Y26: =IF(#REF!=$X$3,1,"") -> #REF! | Z26: =IF(F26=$Z$3,1,"") | AA26: =IF(F26=$AA$3,1,"") | AB26: =IF(F26=$AB$3,1,"") | AC26: =IF(F26=$AC$3,1,"") | AD26: =IF(F26=$AE$3,1,"")
A27: =IF(B27="","",A26+1) -> 23 | B27: Madonna Heights Development Sdn. Bhd. | C27: =IF(B26="","","vs") -> vs | D27: MPAJ | E27: 2010 | F27: DITANGGUHKAN | H27: Permohonan Kebenaran Merancang Secara Serentak Dengan Menambah Syarat Nyata Tanah (Seksyen 124 (1) (C), Ktn Daripada Tapak Institusi Kepada Tapak Institusi Dan Bangunan Kediaman Bagi Cadangan Skim Perumahan Berpagar (‘Gated Community’) Mengandungi 15 Unit Rumah Sesebuah (Zero Lot) 3 Tingkat Dan 160 Unit Kondominium Termasuk 5 Tingkat Aras Bawah Di Atas Sebahagian Lot 389, Mukim Ulu Kelang, Daerah Gombak Selangor Darul Ehsan. | M27: =IF(D27=$M$3,1,"") | N27: =IF(D27=$N$3,1,"") -> 1 | O27: =IF(D27=$O$3,1,"") | P27: =IF(D27=$P$3,1,"") | Q27: =IF(D27=$Q$3,1,"") | R27: =IF(D27=$R$3,1,"") | S27: =IF(D27=$S$3,1,"") | T27: =IF(D27=$T$3,1,"") | U27: =IF(D27=$U$3,1,"") | V27: =IF(D27=$V$3,1,"") | W27: =IF(D27=$W$3,1,"") | X27: =IF(D27=$X$3,1,"") | Y27: =IF(#REF!=$X$3,1,"") -> #REF! | Z27: =IF(F27=$Z$3,1,"") | AA27: =IF(F27=$AA$3,1,"") | AB27: =IF(F27=$AB$3,1,"") | AC27: =IF(F27=$AC$3,1,"") | AD27: =IF(F27=$AE$3,1,"")
A28: =IF(B28="","",A27+1) -> 24 | B28: Spectacular Sdn. Bhd. | C28: =IF(B27="","","vs") -> vs | D28: MPAJ | E28: 2010 | F28: BERSETUJU | H28: Permohonan Kebenaran Merancang Bagi Pembangunan Skim ‘Gated Community’ Di Bawah Seksyen 6(1a) Akta 318 (Akta Hakmilik Strata 1985) Yang Mengandungi Pembangunan 29 Unit Villa 3 ½ Tingkat Dan 12 Unit Rumah Kos Sederhana 4 Tingkat Di Atas Lot 5, Seksyen 2, Jalan 2, Taman Sri Ukay, Mukim Hulu Kelang, Daerah Gombak, Selangor Darul Ehsan. | M28: =IF(D28=$M$3,1,"") | N28: =IF(D28=$N$3,1,"") -> 1 | O28: =IF(D28=$O$3,1,"") | P28: =IF(D28=$P$3,1,"") | Q28: =IF(D28=$Q$3,1,"") | R28: =IF(D28=$R$3,1,"") | S28: =IF(D28=$S$3,1,"") | T28: =IF(D28=$T$3,1,"") | U28: =IF(D28=$U$3,1,"") | V28: =IF(D28=$V$3,1,"") | W28: =IF(D28=$W$3,1,"") | X28: =IF(D28=$X$3,1,"") | Y28: =IF(#REF!=$X$3,1,"") -> #REF! | Z28: =IF(F28=$Z$3,1,"") | AA28: =IF(F28=$AA$3,1,"") | AB28: =IF(F28=$AB$3,1,"") | AC28: =IF(F28=$AC$3,1,"") | AD28: =IF(F28=$AE$3,1,"")
A29: =IF(B29="","",A28+1) -> 25 | B29: Jabatan Penjara Malaysia | C29: =IF(B29="","","vs") -> vs | D29: MPSpg | E29: 2011 | F29: BERSETUJU | G29: bil 3/2011 | H29: Cadangan Pembinaan Pusat Latihan Juvana Penjara Malaysia Di Atas Lot 2238 Mukim Dengkil, Daerah Sepang, Selangor Darul Ehsan. | M29: =IF(D29=$M$3,1,"") | N29: =IF(D29=$N$3,1,"") | O29: =IF(D29=$O$3,1,"") | P29: =IF(D29=$P$3,1,"") | Q29: =IF(D29=$Q$3,1,"") | R29: =IF(D29=$R$3,1,"") | S29: =IF(D29=$S$3,1,"") | T29: =IF(D29=$T$3,1,"") | U29: =IF(D29=$U$3,1,"") | V29: =IF(D29=$V$3,1,"") | W29: =IF(D29=$W$3,1,"") -> 1 | X29: =IF(D29=$X$3,1,"") | Y29: =IF(#REF!=$X$3,1,"") -> #REF! | Z29: =IF(F29=$Z$3,1,"") | AA29: =IF(F29=$AA$3,1,"") | AB29: =IF(F29=$AB$3,1,"") | AC29: =IF(F29=$AC$3,1,"") | AD29: =IF(F29=$AE$3,1,"")
A30: =IF(B30="","",A29+1) -> 26 | B30: Angel Wing(M) Sdn. Bhd. | C30: =IF(B30="","","vs") -> vs | D30: MPAJ | E30: 2011 | F30: DITOLAK | G30: bil 7/2011 | H30: Permohonan Kebenaran Merancang Bagi Cadangan Pindaan Pelan Pembangunan Bercampur Di Atas Lot 96, 149, 452, 453 Dan 454 Mukim Hulu Kelang, Daerah Gombak, Selangor Darul Ehsan. | M30: =IF(D30=$M$3,1,"") | N30: =IF(D30=$N$3,1,"") -> 1 | O30: =IF(D30=$O$3,1,"") | P30: =IF(D30=$P$3,1,"") | Q30: =IF(D30=$Q$3,1,"") | R30: =IF(D30=$R$3,1,"") | S30: =IF(D30=$S$3,1,"") | T30: =IF(D30=$T$3,1,"") | U30: =IF(D30=$U$3,1,"") | V30: =IF(D30=$V$3,1,"") | W30: =IF(D30=$W$3,1,"") | X30: =IF(D30=$X$3,1,"") | Y30: =IF(#REF!=$X$3,1,"") -> #REF! | Z30: =IF(F30=$Z$3,1,"") | AA30: =IF(F30=$AA$3,1,"") | AB30: =IF(F30=$AB$3,1,"") | AC30: =IF(F30=$AC$3,1,"") | AD30: =IF(F30=$AE$3,1,"")
A31: =IF(B31="","",A30+1) -> 27 | B31: Apex Capacity Sdn. Bhd. | C31: =IF(B31="","","vs") -> vs | D31: MBSA | E31: 2011 | F31: BERSETUJU | H31: Permohonan Pembangunan Bercampur Secara Berimilikan Tanah Kerajaan Seluas 29.11 Ekar, Mukim Bukit Raja, Daerah Petaling, Selangor Darul Ehsan. | M31: =IF(D31=$M$3,1,"") | N31: =IF(D31=$N$3,1,"") | O31: =IF(D31=$O$3,1,"") | P31: =IF(D31=$P$3,1,"") | Q31: =IF(D31=$Q$3,1,"") | R31: =IF(D31=$R$3,1,"") -> 1 | S31: =IF(D31=$S$3,1,"") | T31: =IF(D31=$T$3,1,"") | U31: =IF(D31=$U$3,1,"") | V31: =IF(D31=$V$3,1,"") | W31: =IF(D31=$W$3,1,"") | X31: =IF(D31=$X$3,1,"") | Y31: =IF(#REF!=$X$3,1,"") -> #REF! | Z31: =IF(F31=$Z$3,1,"") | AA31: =IF(F31=$AA$3,1,"") | AB31: =IF(F31=$AB$3,1,"") | AC31: =IF(F31=$AC$3,1,"") | AD31: =IF(F31=$AE$3,1,"")
A32: =IF(B32="","",A31+1) -> 28 | B32: Tetuan Meseba Sdn. Bhd + lg 4 permohonan | C32: =IF(B32="","","vs") -> vs | D32: MPKj | E32: 2011 | F32: DITOLAK | H32: Permohonan Kebenaran Merancang Bagi Cadangan Serahbalik dan Berimilik Semula Di Bawah Seksyen 204B, Kanun Tanah Negara Untuk Cadangan Pembangunan Kediaman Sesebuah Di Atas Lot 43818 – 43829, Mukim Cheras, Daerah Hulu Langat, Selangor Darul Ehsan Untuk Tetuan Meseba Sdn. Bhd | M32: =IF(D32=$M$3,1,"") | N32: =IF(D32=$N$3,1,"") | O32: =IF(D32=$O$3,1,"") | P32: =IF(D32=$P$3,1,"") | Q32: =IF(D32=$Q$3,1,"") | R32: =IF(D32=$R$3,1,"") | S32: =IF(D32=$S$3,1,"") | T32: =IF(D32=$T$3,1,"") -> 1 | U32: =IF(D32=$U$3,1,"") | V32: =IF(D32=$V$3,1,"") | W32: =IF(D32=$W$3,1,"") | X32: =IF(D32=$X$3,1,"") | Y32: =IF(#REF!=$X$3,1,"") -> #REF! | Z32: =IF(F32=$Z$3,1,"") | AA32: =IF(F32=$AA$3,1,"") | AB32: =IF(F32=$AB$3,1,"") | AC32: =IF(F32=$AC$3,1,"") | AD32: =IF(F32=$AE$3,1,"")
B33: Tetuan Twin Ridge Sdn. Bhd. | D33: MPAJ | E33: 2011 | F33: DITOLAK | G33: perlu rujuk ksas | M33: =IF(D33=$M$3,1,"") | N33: =IF(D33=$N$3,1,"") -> 1 | O33: =IF(D33=$O$3,1,"") | P33: =IF(D33=$P$3,1,"") | Q33: =IF(D33=$Q$3,1,"") | R33: =IF(D33=$R$3,1,"") | S33: =IF(D33=$S$3,1,"") | T33: =IF(D33=$T$3,1,"") | U33: =IF(D33=$U$3,1,"") | V33: =IF(D33=$V$3,1,"") | W33: =IF(D33=$W$3,1,"") | X33: =IF(D33=$X$3,1,"") | Y33: =IF(#REF!=$X$3,1,"") -> #REF! | Z33: =IF(F33=$Z$3,1,"") | AB33: =IF(F33=$AB$3,1,"") | AC33: =IF(F33=$AC$3,1,"") | AD33: =IF(F33=$AE$3,1,"")
B34: Tetuan Taman TAR Development Sdn. Bhd. | D34: MPAJ | E34: 2011 | F34: DITOLAK | G34: perlu rujuk ksas | M34: =IF(D34=$M$3,1,"") | N34: =IF(D34=$N$3,1,"") -> 1 | O34: =IF(D34=$O$3,1,"") | P34: =IF(D34=$P$3,1,"") | Q34: =IF(D34=$Q$3,1,"") | R34: =IF(D34=$R$3,1,"") | S34: =IF(D34=$S$3,1,"") | T34: =IF(D34=$T$3,1,"") | U34: =IF(D34=$U$3,1,"") | V34: =IF(D34=$V$3,1,"") | W34: =IF(D34=$W$3,1,"") | X34: =IF(D34=$X$3,1,"") | Y34: =IF(#REF!=$X$3,1,"") -> #REF! | Z34: =IF(F34=$Z$3,1,"") | AB34: =IF(F34=$AB$3,1,"") | AC34: =IF(F34=$AC$3,1,"") | AD34: =IF(F34=$AE$3,1,"")
A35: =IF(B35="","",A32+1) -> 29 | B35: Cyberview Sdn. Bhd. (Tetuan Messrs. Myvilla Development Sdn. Bhd.) | C35: =IF(B35="","","vs") -> vs | D35: MPSpg | E35: 2011 | F35: BERSETUJU | H35: Permohonan Kebenaran Merancang Bagi Cadangan Pembangunan : I. Perumahan Berkembar 2 Tingkat (52 Unit) Ii. Perumahan Berkembar 3 Tingkat (164 Unit) Iii. Perumahan Sesebuah 3 Tingkat (5 Unit) Iv. 1 Unit Surau Dan V. 1 Unit Rumah Pengawal Di Bawah Skim ‘Guarded & Gated Community’ Mengikut Seksyen 6(1a) Akta 318 (Akta Hakmilik Strata 1985) Di Atas Pt 26774 Seluas 34.86 Ekar, Jalan B15 (Baru) Cyberjaya, Mukim Dengkil, Daerah Sepang, Selangor Darul Ehsan. | M35: =IF(D35=$M$3,1,"") | N35: =IF(D35=$N$3,1,"") | O35: =IF(D35=$O$3,1,"") | P35: =IF(D35=$P$3,1,"") | Q35: =IF(D35=$Q$3,1,"") | R35: =IF(D35=$R$3,1,"") | S35: =IF(D35=$S$3,1,"") | T35: =IF(D35=$T$3,1,"") | U35: =IF(D35=$U$3,1,"") | V35: =IF(D35=$V$3,1,"") | W35: =IF(D35=$W$3,1,"") -> 1 | X35: =IF(D35=$X$3,1,"") | Y35: =IF(#REF!=$X$3,1,"") -> #REF! | Z35: =IF(F35=$Z$3,1,"") | AA35: =IF(F35=$AA$3,1,"") | AB35: =IF(F35=$AB$3,1,"") | AC35: =IF(F35=$AC$3,1,"") | AD35: =IF(F35=$AE$3,1,"")
A36: =IF(B36="","",A35+1) -> 30 | B36: Triple Esteem Sdn. Bhd. | C36: =IF(B36="","","vs") -> vs | D36: MPAJ | E36: 2011 | F36: BERSETUJU | H36: Permohonan Kebenaran Merancang Bagi Membina 1 Unit Rumah Sesebuah 3 Tingkat (Termasuk 1 Separa Bawah Tanah) Di Atas Lot 6842 (4784), Jalan Teberau 1, Taman Ukay Heights, Bandar Ulu Klang, Daerah Gombak, Selangor Darul Ehsan | M36: =IF(D36=$M$3,1,"") | N36: =IF(D36=$N$3,1,"") -> 1 | O36: =IF(D36=$O$3,1,"") | P36: =IF(D36=$P$3,1,"") | Q36: =IF(D36=$Q$3,1,"") | R36: =IF(D36=$R$3,1,"") | S36: =IF(D36=$S$3,1,"") | T36: =IF(D36=$T$3,1,"") | U36: =IF(D36=$U$3,1,"") | V36: =IF(D36=$V$3,1,"") | W36: =IF(D36=$W$3,1,"") | X36: =IF(D36=$X$3,1,"") | Y36: =IF(#REF!=$X$3,1,"") -> #REF! | Z36: =IF(F36=$Z$3,1,"") | AA36: =IF(F36=$AA$3,1,"") | AB36: =IF(F36=$AB$3,1,"") | AC36: =IF(F36=$AC$3,1,"") | AD36: =IF(F36=$AE$3,1,"")
A37: =IF(B37="","",A36+1) -> 31 | B37: Graham Murray Davidson | C37: =IF(B37="","","vs") -> vs | D37: MPAJ | E37: 2011 | F37: BERSETUJU | H37: Permohonan Kebenaran Merancang Secara Serentak Dengan Tukar Syarat Nyata Tanah Daripada Tiada Kepada Kediaman bagi Membina Sebuah Banglo 3 Tingkat Beserta Bawah Tanah Dan Satu Kolam Renang Di Atas Lot 1614 Taman Ukay Heights, Mukim Ulu Kelang, Daerah Gombak, Selangor | M37: =IF(D37=$M$3,1,"") | N37: =IF(D37=$N$3,1,"") -> 1 | O37: =IF(D37=$O$3,1,"") | P37: =IF(D37=$P$3,1,"") | Q37: =IF(D37=$Q$3,1,"") | R37: =IF(D37=$R$3,1,"") | S37: =IF(D37=$S$3,1,"") | T37: =IF(D37=$T$3,1,"") | U37: =IF(D37=$U$3,1,"") | V37: =IF(D37=$V$3,1,"") | W37: =IF(D37=$W$3,1,"") | X37: =IF(D37=$X$3,1,"") | Y37: =IF(#REF!=$X$3,1,"") -> #REF! | Z37: =IF(F37=$Z$3,1,"") | AA37: =IF(F37=$AA$3,1,"") | AB37: =IF(F37=$AB$3,1,"") | AC37: =IF(F37=$AC$3,1,"") | AD37: =IF(F37=$AE$3,1,"")
A38: =IF(B38="","",A37+1) -> 32 | B38: Paul Leslie Smith | C38: =IF(B38="","","vs") -> vs | D38: MPS | E38: 2011 | F38: BERSETUJU | H38: Permohonan Kebenaran Merancang Secara Serentak Dengan Tukar Syarat Nyata Tanah Daripada Tiada Kepada Kediaman bagi Meroboh Dan Membina Semula Sebuah Banglo 3 Tingkat Beserta Bawah Tanah Dan Satu Kolam Renang Di Atas Lot 1615 Taman Ukay Heights, Mukim Ulu Kelang, Daerah Gombak, Selangor | M38: =IF(D38=$M$3,1,"") | N38: =IF(D38=$N$3,1,"") | O38: =IF(D38=$O$3,1,"") | P38: =IF(D38=$P$3,1,"") | Q38: =IF(D38=$Q$3,1,"") | R38: =IF(D38=$R$3,1,"") | S38: =IF(D38=$S$3,1,"") | T38: =IF(D38=$T$3,1,"") | U38: =IF(D38=$U$3,1,"") -> 1 | V38: =IF(D38=$V$3,1,"") | W38: =IF(D38=$W$3,1,"") | X38: =IF(D38=$X$3,1,"") | Y38: =IF(#REF!=$X$3,1,"") -> #REF! | Z38: =IF(F38=$Z$3,1,"") | AA38: =IF(F38=$AA$3,1,"") | AB38: =IF(F38=$AB$3,1,"") | AC38: =IF(F38=$AC$3,1,"") | AD38: =IF(F38=$AE$3,1,"")
A39: =IF(B39="","",A38+1) -> 33 | B39: Ilona Russell Nee Iona Finnigan | C39: =IF(B39="","","vs") -> vs | D39: MPAJ | E39: 2011 | F39: BERSETUJU | H39: Permohonan Kebenaran Merancang Secara Serentak Dengan Tukar Syarat Nyata Tanah Daripada Tiada Kepada Kediaman bagi Meroboh Dan Membina Semula Sebuah Banglo 3 Tingkat Beserta Bawah Tanah Dan Satu Kolam Renang Di Atas Lot 1616 Taman Ukay Heights, Mukim Ulu Kelang, Daerah Gombak, Selangor | M39: =IF(D39=$M$3,1,"") | N39: =IF(D39=$N$3,1,"") -> 1 | O39: =IF(D39=$O$3,1,"") | P39: =IF(D39=$P$3,1,"") | Q39: =IF(D39=$Q$3,1,"") | R39: =IF(D39=$R$3,1,"") | S39: =IF(D39=$S$3,1,"") | T39: =IF(D39=$T$3,1,"") | U39: =IF(D39=$U$3,1,"") | V39: =IF(D39=$V$3,1,"") | W39: =IF(D39=$W$3,1,"") | X39: =IF(D39=$X$3,1,"") | Y39: =IF(#REF!=$X$3,1,"") -> #REF! | Z39: =IF(F39=$Z$3,1,"") | AA39: =IF(F39=$AA$3,1,"") | AB39: =IF(F39=$AB$3,1,"") | AC39: =IF(F39=$AC$3,1,"") | AD39: =IF(F39=$AE$3,1,"")
A40: =IF(B40="","",A39+1) -> 34 | B40: SK Land & Property Sdn. Bhd. | C40: =IF(B40="","","vs") -> vs | D40: MPS | E40: 2011 | F40: DITOLAK | H40: Permohonan Kebenaran Merancang Pelan Susunatur Bagi Cadangan Membina Sebuah Bangunan ‘Cold Room’ 5 Tingkat Di Atas Lot PT 31117 (Lot 1713), Mukim Batu, Daerah Gombak, Selangor Darul Ehsan | I40: x | M40: =IF(D40=$M$3,1,"") | N40: =IF(D40=$N$3,1,"") | O40: =IF(D40=$O$3,1,"") | P40: =IF(D40=$P$3,1,"") | Q40: =IF(D40=$Q$3,1,"") | R40: =IF(D40=$R$3,1,"") | S40: =IF(D40=$S$3,1,"") | T40: =IF(D40=$T$3,1,"") | U40: =IF(D40=$U$3,1,"") -> 1 | V40: =IF(D40=$V$3,1,"") | W40: =IF(D40=$W$3,1,"") | X40: =IF(D40=$X$3,1,"") | Y40: =IF(#REF!=$X$3,1,"") -> #REF! | Z40: =IF(F40=$Z$3,1,"") | AA40: =IF(F40=$AA$3,1,"") | AB40: =IF(F40=$AB$3,1,"") | AC40: =IF(F40=$AC$3,1,"") | AD40: =IF(F40=$AE$3,1,"")
A41: =IF(B41="","",A40+1) -> 35 | B41: Tenterajaya Sdn. Bhd. (Aman Kemensah Sdn. Bhd.) | C41: =IF(B41="","","vs") -> vs | D41: MPAJ | E41: 2011 | F41: DITANGGUHKAN | H41: Permohonan Kebenaran Merancang Bagi Tujuan Penyerahan Balik Dan Pemberimilikan Semula Di Bawahseksyen 204, Ktn Untuk Pembangunan Perumahan Skim Komuniti Berpagar Di Bawah Seksyen 6 (1a) Akta 318 (Akta Hakmilik Strata 1985) Di Atas Lot 584, 585 Dan 599 Seluas 14.72 Ekar Mukim Ulu Klang Daerah Gombak, Selangor Darul Ehsan | M41: =IF(D41=$M$3,1,"") | N41: =IF(D41=$N$3,1,"") -> 1 | O41: =IF(D41=$O$3,1,"") | P41: =IF(D41=$P$3,1,"") | Q41: =IF(D41=$Q$3,1,"") | R41: =IF(D41=$R$3,1,"") | S41: =IF(D41=$S$3,1,"") | T41: =IF(D41=$T$3,1,"") | U41: =IF(D41=$U$3,1,"") | V41: =IF(D41=$V$3,1,"") | W41: =IF(D41=$W$3,1,"") | X41: =IF(D41=$X$3,1,"") | Y41: =IF(#REF!=$X$3,1,"") -> #REF! | Z41: =IF(F41=$Z$3,1,"") | AA41: =IF(F41=$AA$3,1,"") | AB41: =IF(F41=$AB$3,1,"") | AC41: =IF(F41=$AC$3,1,"") | AD41: =IF(F41=$AE$3,1,"")
...

Sheet Sheet3
A1: JAWATANKUASA TEKNIKAL
A2: PEMBANGUNAN KAWASAN SENSITIF ALAM SEKITAR
A3: NEGERI SELANGOR
A5: BILANGAN PERMOHONAN 2010 - OKTOBER 2025
A7: TAHUN | B7: BIL PERMOHONAN | C7: BERSETUJU | D7: DITOLAK | E7: DITANGGUHKAN | F7: TARIK DIRI
A8: 2010 | B8: 24 | C8: 20 | D8: 0 | E8: 4 | F8: 0
A9: 2011 | B9: 37 | C9: 24 | D9: 9 | E9: 4 | F9: 0
A10: 2012 | B10: =COUNTIF(rekod!E6:E525,A10) -> 14 | C10: =COUNTIF(rekod!F68:F81,C7) -> 12 | D10: =COUNTIF(rekod!F68:F81,D7) -> 2 | E10: =COUNTIF(rekod!F68:F81,E7) -> 0 | F10: =COUNTIF(rekod!F68:F81,F7) -> 0
A11: 2013 | B11: =COUNTIF(rekod!E7:E526,A11) -> 18 | C11: =COUNTIF(rekod!F82:F99,C7) -> 12 | D11: =COUNTIF(rekod!F82:F99,D7) -> 2 | E11: =COUNTIF(rekod!F82:F99,E7) -> 3 | F11: =COUNTIF(rekod!F82:F99,F7) -> 1
A12: 2014 | B12: =COUNTIF(rekod!E8:E527,A12) -> 16 | C12: =COUNTIF(rekod!$F$100:$F$115,$C$7) -> 13 | D12: =COUNTIF(rekod!$F$100:$F$115,D$7) -> 2 | E12: =COUNTIF(rekod!$F$100:$F$115,E$7) -> 1 | F12: =COUNTIF(rekod!$F$100:$F$115,F$7) -> 0
A13: 2015 | B13: =COUNTIF(rekod!E9:E528,A13) -> 23 | C13: =COUNTIF(rekod!$F$116:$F$138,C$7) -> 20 | D13: =COUNTIF(rekod!$F$116:$F$138,D$7) -> 1 | E13: =COUNTIF(rekod!$F$116:$F$138,E$7) -> 2 | F13: =COUNTIF(rekod!$F$116:$F$138,F$7) -> 0
A14: 2016 | B14: =COUNTIF(rekod!E10:E529,A14) -> 9 | C14: =COUNTIF(rekod!$F$139:$F$147,C$7) -> 5 | D14: =COUNTIF(rekod!$F$139:$F$147,D$7) -> 0 | E14: =COUNTIF(rekod!$F$139:$F$147,E$7) -> 3 | F14: =COUNTIF(rekod!$F$139:$F$147,F$7) -> 1
A15: 2017 | B15: =COUNTIF(rekod!E11:E530,A15) -> 18 | C15: =COUNTIF(rekod!$F$148:$F$165,C$7) -> 16 | D15: =COUNTIF(rekod!$F$148:$F$165,D$7) -> 2 | E15: =COUNTIF(rekod!$F$148:$F$165,E$7) -> 0 | F15: =COUNTIF(rekod!$F$148:$F$165,F$7) -> 0
A16: 2018 | B16: =COUNTIF(rekod!E12:E531,A16) -> 19 | C16: =COUNTIF(rekod!$F$166:$F$184,C$7) -> 17 | D16: =COUNTIF(rekod!$F$166:$F$184,D$7) -> 0 | E16: =COUNTIF(rekod!$F$166:$F$184,E$7) -> 2 | F16: =COUNTIF(rekod!$F$166:$F$184,F$7) -> 0
A17: 2019 | B17: =COUNTIF(rekod!E13:E532,A17) -> 20 | C17: =COUNTIF(rekod!$F$185:$F$204,C$7) -> 17 | D17: =COUNTIF(rekod!$F$185:$F$204,D$7) -> 2 | E17: =COUNTIF(rekod!$F$185:$F$204,E$7) -> 1 | F17: =COUNTIF(rekod!$F$185:$F$204,F$7) -> 0
A18: 2020 | B18: =COUNTIF(rekod!E14:E533,A18) -> 10 | C18: =COUNTIF(rekod!$F$205:$F$214,C$7) -> 7 | D18: =COUNTIF(rekod!$F$205:$F$214,D$7) -> 3 | E18: =COUNTIF(rekod!$F$205:$F$214,E$7) -> 0 | F18: =COUNTIF(rekod!$F$205:$F$214,F$7) -> 0
A19: 2021 | B19: =COUNTIF(rekod!E15:E534,A19) -> 10 | C19: =COUNTIF(rekod!$F$215:$F$224,C$7) -> 9 | D19: =COUNTIF(rekod!$F$215:$F$224,D$7) -> 0 | E19: =COUNTIF(rekod!$F$215:$F$224,E$7) -> 1 | F19: =COUNTIF(rekod!$F$215:$F$224,F$7) -> 0
A20: 2022 | B20: =COUNTIF(rekod!E13:E532,A20) -> 24 | C20: =COUNTIF(rekod!$F$225:$F$249,C$7) -> 15 | D20: =COUNTIF(rekod!$F$225:$F$249,D$7) -> 9 | E20: =COUNTIF(rekod!$F$225:$F$249,E$7) -> 0 | F20: =COUNTIF(rekod!$F$225:$F$249,F$7) -> 0
A21: 2023 | B21: =COUNTIF(rekod!E14:E533,A21) -> 28 | C21: =COUNTIF(rekod!$F$250:$F$278,C$7) -> 24 | D21: =COUNTIF(rekod!$F$250:$F$278,D$7) -> 0 | E21: =COUNTIF(rekod!$F$250:$F$278,E$7) -> 3 | F21: =COUNTIF(rekod!$F$250:$F$278,F$7) -> 1
A22: 2024 | B22: =COUNTIF(rekod!E15:E534,A22) -> 34 | C22: =COUNTIF(rekod!$F$279:$F$314,C$7) -> 27 | D22: =COUNTIF(rekod!$F$279:$F$314,D$7) -> 6 | E22: =COUNTIF(rekod!$F$279:$F$314,E$7) -> 1 | F22: =COUNTIF(rekod!$F$279:$F$314,F$7) -> 0
A23: 2025 | B23: =COUNTIF(rekod!E16:E535,A23) -> 36 | C23: =COUNTIF(rekod!$F$315:$F$348,C$7) -> 24 | D23: =COUNTIF(rekod!$F$315:$F$348,D$7) -> 4 | E23: =COUNTIF(rekod!$F$315:$F$348,E$7) -> 2 | F23: =COUNTIF(rekod!$F$315:$F$348,F$7) -> 1
A24: 2026 | B24: =COUNTIF(rekod!E17:E536,A24) -> 30
A25: 2027 | B25: =COUNTIF(rekod!E18:E537,A25) -> 0
A26: 2028 | B26: =COUNTIF(rekod!E19:E538,A26) -> 0
A27: 2029 | B27: =COUNTIF(rekod!E20:E539,A27) -> 0
A28: 2030 | B28: =COUNTIF(rekod!E21:E540,A28) -> 0
A29: JUMLAH | B29: =SUM(B8:B28) -> 370 | C29: =SUM(C8:C28) -> 262 | D29: =SUM(D8:D28) -> 42 | E29: =SUM(E8:E28) -> 27 | F29: =SUM(F8:F28) -> 4
C30: =SUM(C29:F29) -> 335

Sheet mesy pengarah neg
A1: JAWATANKUASA TEKNIKAL PEMBANGUNAN KAWASAN SENSITIF ALAM SEKITAR | J1: Januari
A2: NEGERI SELANGOR 2019-2022
J3: Jun
A4: H. Kes-Kes Lembaga Rayuan. | J4: Julai
A5: ="Sebanyak "&TEXT(#REF!,"0")&" kes telah diterima oleh Lembaga Rayuan sehingga "&TEXT(#REF!,"0")&" 2014. Status terhadap kes-kes tersebut adalah seperti berikut:-" -> #REF! | J5: Ogos
B6: i. Bersetuju | C6: : | D6: =rekod!Z525 -> 143 | J6: September
B7: ii. Ditangguhkan | C7: : | D7: =rekod!AB525 -> 143 | J7: Oktober
B8: iii. Ditolak | C8: : | D8: =rekod!AA525 -> 143 | J8: November
B9: iv. Tarik Diri | C9: : | D9: =rekod!AC525 -> 144 | J9: Disember
B10: JUMLAH | C10: : | D10: =SUM(D6:D9) -> 573
A13: BIL. | B13: PEMOHON | C13: PBT | D13: TAHUN | E13: PERKARA | F13: KEPUTUSAN
A14: 1 | B14: =IF(A14="","",UPPER(rekod!B4)) -> PPC GLOMAC SDN. BHD. | C14: =IF(B14="","",rekod!D4) -> MBSA | D14: =IF(B14="","",rekod!E4) -> 2010 | E14: =IF(B14="","",rekod!H4) -> Permohonan Serahbalik Dan Berimilik Semula Di Bawah Seksyen 204D KTN, Di Atas Lot 243, 395 Dan 397 Mukim Sungai Buloh, Daerah Petaling, Seksyen U17, 40160 Shah Alam, Selangor Darul Ehsan. | F14: =IF(rekod!F4="","",rekod!F4) -> BERSETUJU | I14: BERSETUJU
A15: =IF(rekod!B5="","",A14+1) -> 2 | B15: =IF(A15="","",UPPER(rekod!B5)) -> TURF TECH SDN. BHD. | C15: =IF(B15="","",rekod!D5) -> MPS | D15: =IF(B15="","",rekod!E5) -> 2010 | E15: =IF(B15="","",rekod!H5) -> Permohonan Kelulusan Secara Serentak Bagi Pelan Kebenaran Merancang, Pelan Kerja Tanah, Pelan Jalan Dan Perparitan, Pelan Landskap, Pelan Bangunan Perumahan Di Atas Lot 163, Bandar Selayang, Daerah Gombak, Selangor Darul Ehsan. | F15: =IF(rekod!F5="","",rekod!F5) -> BERSETUJU | I15: DITOLAK
A16: =IF(rekod!B6="","",A15+1) -> 3 | B16: =IF(A16="","",UPPER(rekod!B6)) -> SIN HEAP LEE DEVELOPMENT SDN. BHD. | C16: =IF(B16="","",rekod!D6) -> MPKj | D16: =IF(B16="","",rekod!E6) -> 2010 | E16: =IF(B16="","",rekod!H6) -> Permohonan Kebenaran Merancang Cadangan Serahbalik Dan Berimilikan Semula Tanah Di Bawah Seksyen 204A Kanun Tanah Negara (KTN) Bagi Pembangunan Perumahan, Di Atas Lot PT.1495/1, PT.1495/2, PT.1495/3 Dan PT1495/4, Mukim Cheras, Daerah Hulu Langat, Selangor Darul Ehsan. | F16: =IF(rekod!F6="","",rekod!F6) -> BERSETUJU | I16: DITANGGUHKAN
A17: =IF(rekod!B7="","",A16+1) -> 4 | B17: =IF(A17="","",UPPER(rekod!B7)) -> TRANS LOYAL DEVELOPMENT SDN. BHD. | C17: =IF(B17="","",rekod!D7) -> MPKj | D17: =IF(B17="","",rekod!E7) -> 2010 | E17: =IF(B17="","",rekod!H7) -> Permohonan Pindaan Kebenaran Merancang Terhadap Sebahagian Pelan Susunatur Yang Telah Diluluskan (Bil. Surat : (12) Dlm. MPKJ PB/KM1/68-2002) Bagi Cadangan Pembangunan Perumahan Dan Perniagaan, Di Atas Pt 69787 (Sebahagian Lot Asal Lot 41146) Mukim Kajang, Daerah Hulu Langat, Selangor Darul Ehsan. | F17: =IF(rekod!F7="","",rekod!F7) -> BERSETUJU | I17: TARIK DIRI
A18: =IF(rekod!B8="","",A17+1) -> 5 | B18: =IF(A18="","",UPPER(rekod!B8)) -> SUNWAY TERMUNING SDN. BHD. | C18: =IF(B18="","",rekod!D8) -> MPKj | D18: =IF(B18="","",rekod!E8) -> 2010 | E18: =IF(B18="","",rekod!H8) -> Permohonan Kebenaran Merancang Untuk Pelan Susunatur Di Atas Lot 1316, 1352, 1355, 1401-1406, 1408-1410, 1412-1413, 1683-1684 Dan Sebahagian Lot 46953 (Lot 1351), Mukim Cheras, Daerah Hulu Langat, Selangor Darul Ehsan. | F18: =IF(rekod!F8="","",rekod!F8) -> DITANGGUHKAN
A19: =IF(rekod!B9="","",A18+1) -> 6 | B19: =IF(A19="","",UPPER(rekod!B9)) -> PRISMA CABARAN SDN. BHD. | C19: =IF(B19="","",rekod!D9) -> MPSpg | D19: =IF(B19="","",rekod!E9) -> 2010 | E19: =IF(B19="","",rekod!H9) -> Permohonan Kebenaran Merancang Bagi Cadangan Serah Balik Dan Pemberimilikan Semula Tanah, Di Bawah Seksyen 204d, Kanun Tanah Negara, Untuk Pembangunan Sekolah Agama Kiblah, Di Atas Lot 30774 (No. Hakmilik Pn) 43378), Mukim Dengkil, Daerah Sepang, Selangor Darul Ehsan Untuk Tetuan Prisma Cabaran Sdn. Bhd. | F19: =IF(rekod!F9="","",rekod!F9) -> BERSETUJU
A20: =IF(rekod!B10="","",A19+1) -> 7 | B20: =IF(A20="","",UPPER(rekod!B10)) -> PKNS DAN SPANLAND SDN. BHD. | C20: =IF(B20="","",rekod!D10) -> MPS | D20: =IF(B20="","",rekod!E10) -> 2010 | E20: =IF(B20="","",rekod!H10) -> Permohonan Kebenaran Merancang Bagi Pindaan Pelan Susunatur (Bil. : PKNS/SPANLAND(PR)/G/0411PL1-A) bertarikh 31hb. Januari 2008) di atas lot PT 24263 HS(D) 49212 Lot PT 27264 HS (D) 49213, Lot PT 27265 HS(D) 52089 Dan Tanah Kerajaan Milik PKNS, Mukim Rawang, Daerah Gombak, Selangor | F20: =IF(rekod!F10="","",rekod!F10) -> BERSETUJU
A21: =IF(rekod!B11="","",A20+1) -> 8 | B21: =IF(A21="","",UPPER(rekod!B11)) -> DACING KOTA SDN. BHD. | C21: =IF(B21="","",rekod!D11) -> MBSA | D21: =IF(B21="","",rekod!E11) -> 2010 | E21: =IF(B21="","",rekod!H11) -> Permohonan Kebenaran Merancang Pelan Susunatur Bagi Pembangunan Perumahan Di Atas Tanah Seluas 16.80 Ekar, Mukim Bukit Raja, Daerah Petaling, Seksyen U10, Shah Alam | F21: =IF(rekod!F11="","",rekod!F11) -> BERSETUJU
A22: =IF(rekod!B12="","",A21+1) -> 9 | B22: =IF(A22="","",UPPER(rekod!B12)) -> KENANGAN MOTIVASI SDN. BHD. | C22: =IF(B22="","",rekod!D12) -> MBSA | D22: =IF(B22="","",rekod!E12) -> 2010 | E22: =IF(B22="","",rekod!H12) -> Permohonan Kebenaran Merancang Pelan Susunatur Bagi Pembangunan Perumahan Di Atas Lot Kompartment 32, Tanah Hutan Simpan Bukit Cherakah Seluas 100 Ekar, Mukim Bukit Raja, Daerah Petaling, Seksyen U10, Shah Alam Selangor | F22: =IF(rekod!F12="","",rekod!F12) -> BERSETUJU
A23: =IF(rekod!B13="","",A22+1) -> 10 | B23: =IF(A23="","",UPPER(rekod!B13)) -> BASCO SDN. BHD. | C23: =IF(B23="","",rekod!D13) -> MBSA | D23: =IF(B23="","",rekod!E13) -> 2010 | E23: =IF(B23="","",rekod!H13) -> Permohonan Kebenaran Merancang Pelan Susunatur Bagi Cadangan Pembangunan Perumahan Dan Perdagangan, Di Atas Tanah Pemberimilikan Seluas 200 Ekar, Seksyen U10, Shah Alam, Mukim Bukit Raja, Daerah Petaling, Selangor Darul Ehsan | F23: =IF(rekod!F13="","",rekod!F13) -> BERSETUJU
A24: =IF(rekod!B14="","",A23+1) -> 11 | B24: =IF(A24="","",UPPER(rekod!B14)) -> TPPT SDN. BHD. | C24: =IF(B24="","",rekod!D14) -> MPS | D24: =IF(B24="","",rekod!E14) -> 2010 | E24: =IF(B24="","",rekod!H14) -> Permohonan Kebenaran Merancang Bagi Cadangan Pelan Induk Di Bukit Serai, Mukim Rawang, Daerah Gombak, Selangor Darul Ehsan | F24: =IF(rekod!F14="","",rekod!F14) -> BERSETUJU
A25: =IF(rekod!B15="","",A24+1) -> 12 | B25: =IF(A25="","",UPPER(rekod!B15)) -> GRANSTEP DEVELOPMENT SDN. BHD. | C25: =IF(B25="","",rekod!D15) -> MPAJ | D25: =IF(B25="","",rekod!E15) -> 2010 | E25: =IF(B25="","",rekod!H15) -> Permohonan Kebenaran Merancang Bagi Cadangan Pembangunan Perumahan Di Atas Lot 1287 (PT 30517, HS(D) 34803) Seluas 11.84 hektar (29.28 ekar), Bandar Ampang, Daerah Hulu Langat, Selangor Darul Ehsan Untuk Tetuan Granstep Development Sdn. Bhd. | F25: =IF(rekod!F15="","",rekod!F15) -> DITANGGUHKAN
A26: =IF(rekod!B16="","",A25+1) -> 13 | B26: =IF(A26="","",UPPER(rekod!B16)) -> DIJAYA PROPERTY SDN. BHD. | C26: =IF(B26="","",rekod!D16) -> MPKj | D26: =IF(B26="","",rekod!E16) -> 2010 | E26: =IF(B26="","",rekod!H16) -> Permohonan Pecah Sempadan Dan Tukar Syarat Tanah Secara Serentak Di Bawah Seksyen 124a Kanun Tanah Negara 1965 Dan Pembangunan 90 Unit Rumah Teres Strata Di Bawah Seksyen 6(1a) Akta 318 (Akta Hakmilik Strata 1985) Di Atas Lot 5717 Dan 1953, Mukim Kajang, Daerah Hulu Langat, Selangor Darul Ehsan. | F26: =IF(rekod!F16="","",rekod!F16) -> BERSETUJU
A27: =IF(rekod!B17="","",A26+1) -> 14 | B27: =IF(A27="","",UPPER(rekod!B17)) -> WANGMATIC SDN. BHD. | C27: =IF(B27="","",rekod!D17) -> MPKj | D27: =IF(B27="","",rekod!E17) -> 2010 | E27: =IF(B27="","",rekod!H17) -> Permohonan Kebenaran Merancang Bagi Tujuan Tukar Syarat Daripada Tiada Kepada Bangunan Perumahan Di Bawah Seksyen 124a, Kanun Tanah Negara Di Atas Lot 2717, Mukim Kajang, Daerah Hulu Langat, Selangor Darul Ehsan | F27: =IF(rekod!F17="","",rekod!F17) -> BERSETUJU
A28: =IF(rekod!B18="","",A27+1) -> 15 | B28: =IF(A28="","",UPPER(rekod!B18)) -> PRISMA CABARAN SDN. BHD. | C28: =IF(B28="","",rekod!D18) -> MPSpg | D28: =IF(B28="","",rekod!E18) -> 2010 | E28: =IF(B28="","",rekod!H18) -> Permohonan Kebenaran Merancang Bagi Cadangan Serah Balik Dan Pemberimilikan Semula Tanah Di Bawah Seksyen 204d, Kanun Tanah Negara (Ktn) Untuk Pembangunan Sekolah Agama Kiblah Dan Mahad Tahfiz, Di Atas Lot 30774 No. Hakmilik Pn 49378 (Pt17124), Mukim Dengkil, Daerah Sepang, Selangor Darul Ehsan. | F28: =IF(rekod!F18="","",rekod!F18) -> DITANGGUHKAN
A29: =IF(rekod!B19="","",A28+1) -> 16 | B29: =IF(A29="","",UPPER(rekod!B19)) -> B.U. DEVELOPMENTS SDN. BHD. | C29: =IF(B29="","",rekod!D19) -> MPAJ | D29: =IF(B29="","",rekod!E19) -> 2010 | E29: =IF(B29="","",rekod!H19) -> Permohonan Kebenaran Merancang Bagi Cadangan Pembangunan Perniagaan yang Mengandungi Blok A, Blok B dan Blok C Serta meminda Syarat Nyata Tanah Daripada Bangunan Kediaman Kepada Perniagaan Secara Serentak Di Bawah Seksyen 124A Kanun Tanah Negara (KTN) Di Atas Lot 322 (GM53), Mukim Ulu Kelang, Daerah Gombak, Selangor Darul Ehsan. | F29: =IF(rekod!F19="","",rekod!F19) -> BERSETUJU
... A32: =IF(rekod!B22="","",A31+1) -> 19 | B32: =IF(A32="","",UPPER(rekod!B22)) -> SMS DEVELOPMENT SDN. BHD. | C32: =IF(B32="","",rekod!D22) -> MPKj | D32: =IF(B32="","",rekod!E22) -> 2010 | E32: =IF(B32="","",rekod!H22) -> Permohonan Kebenaran Merancang Bagi Cadangan Pelan Susunatur Industri Berkembar 56 Unit Di Atas Lot 19003 Sekxsyen 19, Bandar Rawang, Daerah Gombak, Selangor Darul Ehsan | F32: =IF(rekod!F22="","",rekod!F22) -> BERSETUJU
A33: =IF(rekod!B24="","",A32+1) -> 20 | B33: =IF(A33="","",UPPER(rekod!B24)) -> MAMMOTH EMPIRE LAND SDN. BHD. | C33: =IF(B33="","",rekod!D24) -> MBPJ | D33: =IF(B33="","",rekod!E24) -> 2010 | E33: =IF(B33="","",rekod!H24) -> Permohonan Kebenaran Merancang Bagi Cadangan Pecah Sempadan Mengikut Seksyen 135 (Kanun Tanah Negara 1965) Dan Pembangunan 795 Unit Rumah Teres 3 Tingkat Serta 1 Tingkat Tempat Letak kereta (Permilikan Berstrata Mengikut Seksyen 6, Akta Hakmilik Strata 1985) Di Atas Lot 44012 HSD 222396, Mukim Sungai Buloh, Daerah Petaling, Selangor Darul Ehsan. | F33: =IF(rekod!F24="","",rekod!F24) -> BERSETUJU
A34: =IF(rekod!B25="","",A33+1) -> 21 | B34: =IF(A34="","",UPPER(rekod!B25)) -> PERMODALAN NEGERI SELANGOR BERHAD (PNSB) | C34: =IF(B34="","",rekod!D25) -> MBPJ | D34: =IF(B34="","",rekod!E25) -> 2010 | E34: =IF(B34="","",rekod!H25) -> Cadangan Projek Perumahan Dimajukan Secara Usahasama Di Antara Setiausaha Kerajaan Negeri Selangor (Perbadanan) Dengan Syarikat Tetuan Agro Fresh (M) Sdn. Bhd. Pembangunan Perumahan Di Atas Lot 23739 (Dahulu Lot 1999), 23740 (Dahulu Lot 3505) Dan 23741 (Lot 3587) Mukim Sungai Buloh Daerah Petaling Selangor Darul Ehsan. | F34: =IF(rekod!F25="","",rekod!F25) -> BERSETUJU
A35: =IF(rekod!B26="","",A34+1) -> 22 | B35: =IF(A35="","",UPPER(rekod!B26)) -> RESTU MANTAP SDN. BHD. | C35: =IF(B35="","",rekod!D26) -> MBSA | D35: =IF(B35="","",rekod!E26) -> 2010 | E35: =IF(B35="","",rekod!H26) -> Permohonan Kebenaran Merancang Bagi Cadangan Pelan Susunatur Perumahan Di Atas Kompartmen 35, Hutan Simpan Bukit Cherakah, Mukim Bukit Raja, Daerah Petaling, Seksyen U10, Shah Alam, Selangor Darul Ehsan. | F35: =IF(rekod!F26="","",rekod!F26) -> BERSETUJU
A36: =IF(rekod!B27="","",A35+1) -> 23 | B36: =IF(A36="","",UPPER(rekod!B27)) -> MADONNA HEIGHTS DEVELOPMENT SDN. BHD. | C36: =IF(B36="","",rekod!D27) -> MPAJ | D36: =IF(B36="","",rekod!E27) -> 2010 | E36: =IF(B36="","",rekod!H27) -> Permohonan Kebenaran Merancang Secara Serentak Dengan Menambah Syarat Nyata Tanah (Seksyen 124 (1) (C), Ktn Daripada Tapak Institusi Kepada Tapak Institusi Dan Bangunan Kediaman Bagi Cadangan Skim Perumahan Berpagar (‘Gated Community’) Mengandungi 15 Unit Rumah Sesebuah (Zero Lot) 3 Tingkat Dan 160 Unit Kondominium Termasuk 5 Tingkat Aras Bawah Di Atas Sebahagian Lot 389, Mukim Ulu Kelang, Daerah Gombak Selangor Darul Ehsan. | F36: =IF(rekod!F27="","",rekod!F27) -> DITANGGUHKAN
A37: =IF(rekod!B28="","",A36+1) -> 24 | B37: =IF(A37="","",UPPER(rekod!B28)) -> SPECTACULAR SDN. BHD. | C37: =IF(B37="","",rekod!D28) -> MPAJ | D37: =IF(B37="","",rekod!E28) -> 2010 | E37: =IF(B37="","",rekod!H28) -> Permohonan Kebenaran Merancang Bagi Pembangunan Skim ‘Gated Community’ Di Bawah Seksyen 6(1a) Akta 318 (Akta Hakmilik Strata 1985) Yang Mengandungi Pembangunan 29 Unit Villa 3 ½ Tingkat Dan 12 Unit Rumah Kos Sederhana 4 Tingkat Di Atas Lot 5, Seksyen 2, Jalan 2, Taman Sri Ukay, Mukim Hulu Kelang, Daerah Gombak, Selangor Darul Ehsan. | F37: =IF(rekod!F28="","",rekod!F28) -> BERSETUJU
A38: =IF(rekod!B29="","",A37+1) -> 25 | B38: =IF(A38="","",UPPER(rekod!B29)) -> JABATAN PENJARA MALAYSIA | C38: =IF(B38="","",rekod!D29) -> MPSpg | D38: =IF(B38="","",rekod!E29) -> 2011 | E38: =IF(B38="","",rekod!H29) -> Cadangan Pembinaan Pusat Latihan Juvana Penjara Malaysia Di Atas Lot 2238 Mukim Dengkil, Daerah Sepang, Selangor Darul Ehsan. | F38: =IF(rekod!F29="","",rekod!F29) -> BERSETUJU
A39: =IF(rekod!B30="","",A38+1) -> 26 | B39: =IF(A39="","",UPPER(rekod!B30)) -> ANGEL WING(M) SDN. BHD. | C39: =IF(B39="","",rekod!D30) -> MPAJ | D39: =IF(B39="","",rekod!E30) -> 2011 | E39: =IF(B39="","",rekod!H30) -> Permohonan Kebenaran Merancang Bagi Cadangan Pindaan Pelan Pembangunan Bercampur Di Atas Lot 96, 149, 452, 453 Dan 454 Mukim Hulu Kelang, Daerah Gombak, Selangor Darul Ehsan. | F39: =IF(rekod!F30="","",rekod!F30) -> DITOLAK
A40: =IF(rekod!B31="","",A39+1) -> 27 | B40: =IF(A40="","",UPPER(rekod!B31)) -> APEX CAPACITY SDN. BHD. | C40: =IF(B40="","",rekod!D31) -> MBSA | D40: =IF(B40="","",rekod!E31) -> 2011 | E40: =IF(B40="","",rekod!H31) -> Permohonan Pembangunan Bercampur Secara Berimilikan Tanah Kerajaan Seluas 29.11 Ekar, Mukim Bukit Raja, Daerah Petaling, Selangor Darul Ehsan. | F40: =IF(rekod!F31="","",rekod!F31) -> BERSETUJU
A41: =IF(rekod!B32="","",A40+1) -> 28 | B41: =IF(A41="","",UPPER(rekod!B32)) -> TETUAN MESEBA SDN. BHD + LG 4 PERMOHONAN | C41: =IF(B41="","",rekod!D32) -> MPKj | D41: =IF(B41="","",rekod!E32) -> 2011 | E41: =IF(B41="","",rekod!H32) -> Permohonan Kebenaran Merancang Bagi Cadangan Serahbalik dan Berimilik Semula Di Bawah Seksyen 204B, Kanun Tanah Negara Untuk Cadangan Pembangunan Kediaman Sesebuah Di Atas Lot 43818 – 43829, Mukim Cheras, Daerah Hulu Langat, Selangor Darul Ehsan Untuk Tetuan Meseba Sdn. Bhd | F41: =IF(rekod!F32="","",rekod!F32) -> DITOLAK
A42: =IF(rekod!B35="","",A41+1) -> 29 | B42: =IF(A42="","",UPPER(rekod!B35)) -> CYBERVIEW SDN. BHD. (TETUAN MESSRS. MYVILLA DEVELOPMENT SDN. BHD.) | C42: =IF(B42="","",rekod!D35) -> MPSpg | D42: =IF(B42="","",rekod!E35) -> 2011 | E42: =IF(B42="","",rekod!H35) -> Permohonan Kebenaran Merancang Bagi Cadangan Pembangunan : I. Perumahan Berkembar 2 Tingkat (52 Unit) Ii. Perumahan Berkembar 3 Tingkat (164 Unit) Iii. Perumahan Sesebuah 3 Tingkat (5 Unit) Iv. 1 Unit Surau Dan V. 1 Unit Rumah Pengawal Di Bawah Skim ‘Guarded & Gated Community’ Mengikut Seksyen 6(1a) Akta 318 (Akta Hakmilik Strata 1985) Di Atas Pt 26774 Seluas 34.86 Ekar, Jalan B15 (Baru) Cyberjaya, Mukim Dengkil, Daerah Sepang, Selangor Darul Ehsan. | F42: =IF(rekod!F35="","",rekod!F35) -> BERSETUJU
A43: =IF(rekod!B36="","",A42+1) -> 30 | B43: =IF(A43="","",UPPER(rekod!B36)) -> TRIPLE ESTEEM SDN. BHD. | C43: =IF(B43="","",rekod!D36) -> MPAJ | D43: =IF(B43="","",rekod!E36) -> 2011 | E43: =IF(B43="","",rekod!H36) -> Permohonan Kebenaran Merancang Bagi Membina 1 Unit Rumah Sesebuah 3 Tingkat (Termasuk 1 Separa Bawah Tanah) Di Atas Lot 6842 (4784), Jalan Teberau 1, Taman Ukay Heights, Bandar Ulu Klang, Daerah Gombak, Selangor Darul Ehsan | F43: =IF(rekod!F36="","",rekod!F36) -> BERSETUJU
A44: =IF(rekod!B37="","",A43+1) -> 31 | B44: =IF(A44="","",UPPER(rekod!B37)) -> GRAHAM MURRAY DAVIDSON | C44: =IF(B44="","",rekod!D37) -> MPAJ | D44: =IF(B44="","",rekod!E37) -> 2011 | E44: =IF(B44="","",rekod!H37) -> Permohonan Kebenaran Merancang Secara Serentak Dengan Tukar Syarat Nyata Tanah Daripada Tiada Kepada Kediaman bagi Membina Sebuah Banglo 3 Tingkat Beserta Bawah Tanah Dan Satu Kolam Renang Di Atas Lot 1614 Taman Ukay Heights, Mukim Ulu Kelang, Daerah Gombak, Selangor | F44: =IF(rekod!F37="","",rekod!F37) -> BERSETUJU
...
